<?xml version="1.0" ?>
<!-- =================================================================================== -->
<!-- |    This document was autogenerated by xacro from PIR-B-ASSY-001-integeration.xacro | -->
<!-- |    EDITING THIS FILE BY HAND IS NOT RECOMMENDED                                 | -->
<!-- =================================================================================== -->
<robot name="pir-b-001">
  <link name="base_footprint"/>
  <link name="base_link">
    <inertial>
      <origin rpy="0 0 0" xyz="0.00464580299161508 -0.00157654781508274 1.29496402264534E-08"/>
      <mass value="0.170619611327794"/>
      <inertia ixx="8.87834221142331E-05" ixy="7.79394477944035E-08" ixz="9.12723410794375E-12" iyy="3.69411152186283E-05" iyz="-1.02575311402571E-11" izz="7.54787982319766E-05"/>
    </inertial>
    <visual>
      <origin rpy="0 0 0" xyz="0 0 0"/>
      <geometry>
        <mesh filename="package://pir-b-001/meshes/base_link.STL"/>
      </geometry>
      <material name="">
        <color rgba="0.2156862745098 0.19607843137255 0.33333333333333 1"/>
      </material>
    </visual>
    <collision>
      <origin rpy="0 0 0" xyz="0 0 0"/>
      <geometry>
        <mesh filename="package://pir-b-001/meshes/base_link.STL"/>
      </geometry>
    </collision>
  </link>
  <joint name="base_joint" type="fixed">
    <parent link="base_footprint"/>
    <child link="base_link"/>
  </joint>
  <link name="right_Link">
    <inertial>
      <origin rpy="0 0 0" xyz="-0.00184881111328208 -4.23784689099552E-07 0.0428862642303592"/>
      <mass value="0.0937706135990428"/>
      <inertia ixx="3.3058401223831E-05" ixy="-8.41485245226076E-11" ixz="-1.68708890047153E-07" iyy="2.54497427915133E-05" iyz="1.89306498798761E-10" izz="1.98487722559132E-05"/>
    </inertial>
    <visual>
      <origin rpy="0 0 0" xyz="0 0 0"/>
      <geometry>
        <mesh filename="package://pir-b-001/meshes/right_Link.STL"/>
      </geometry>
      <material name="brown">
        <color rgba="0.2156862745098 0.29607843137255 0.33333333333333 1"/>
      </material>
    </visual>
    <collision>
      <origin rpy="0 0 0" xyz="0 0 0"/>
      <geometry>
        <mesh filename="package://pir-b-001/meshes/right_Link.STL"/>
      </geometry>
    </collision>
  </link>
  <joint name="right_Linkj" type="continuous">
    <origin rpy="1.57079632679489 0 -3.14159265358979" xyz="-0.0014878 0.0595 0"/>
    <parent link="base_link"/>
    <child link="right_Link"/>
    <axis xyz="-1 0 0"/>
    <limit effort="10" velocity="10"/>
  </joint>
  <link name="right_wheel1">
    <inertial>
      <origin rpy="0 0 0" xyz="-0.000152394722576409 -1.38777878078145E-17 0.00826667615289123"/>
      <mass value="0.00397466978072404"/>
      <inertia ixx="3.60918483675977E-07" ixy="1.65569978578215E-24" ixz="-5.54295173329271E-24" iyy="5.29262126321023E-07" iyz="-2.39172772821026E-13" izz="2.18039563551073E-07"/>
    </inertial>
    <visual>
      <origin rpy="0 0 0" xyz="0 0 0"/>
      <geometry>
        <mesh filename="package://pir-b-001/meshes/right_wheel1.STL"/>
      </geometry>
      <material name="">
        <color rgba="0.792156862745098 0.819607843137255 0.933333333333333 1"/>
      </material>
    </visual>
    <collision>
      <origin rpy="0 0 0" xyz="0 0 0"/>
      <geometry>
        <mesh filename="package://pir-b-001/meshes/right_wheel1.STL"/>
      </geometry>
    </collision>
  </link>
  <joint name="right_wheel1j" type="continuous">
    <origin rpy="3.14159265358979 0 3.14159265358979" xyz="-0.00749999999999901 0 0.120529810536102"/>
    <parent link="right_Link"/>
    <child link="right_wheel1"/>
    <axis xyz="0 0 1"/>
    <limit effort="10" velocity="50"/>
  </joint>
  <link name="right_wheel">
    <inertial>
      <origin rpy="0 0 0" xyz="0 -9.80989718277203E-10 0.00057019000905606"/>
      <mass value="0.06316999034176"/>
      <inertia ixx="2.34601118841819E-05" ixy="6.34235569189726E-13" ixz="1.10459714329623E-15" iyy="1.31801476605567E-05" iyz="1.21434487375606E-10" izz="1.31800680409047E-05"/>
    </inertial>
    <visual>
      <origin rpy="0 0 0" xyz="0 9.80989718277203E-10 0.00057019000905606"/>
      <geometry>
        <mesh filename="package://pir-b-001/meshes/right_wheel.STL"/>
      </geometry>
      <material name="">
        <color rgba="0.2156862745098 0.25 0.333333333333333 1"/>
      </material>
    </visual>
    <collision>
      <origin rpy="0 0 0" xyz="0 9.80989718277203E-10 0.00057019000905606"/>
      <geometry>
        <mesh filename="package://pir-b-001/meshes/right_wheel.STL"/>
      </geometry>
    </collision>
  </link>
  <joint name="right_wheelj" type="continuous">
    <origin rpy="0 0 0" xyz="0 0 0"/>
    <parent link="right_wheel1"/>
    <child link="right_wheel"/>
    <axis xyz="1 0 0"/>
    <limit effort="0" lower="0" upper="0" velocity="0"/>
  </joint>
  <link name="omni1">
    <inertial>
      <origin rpy="0 0 0" xyz="-0.00563003320638717 -2.34501937295545E-08 3.54608361008424E-08"/>
      <mass value="0.0201689077901827"/>
      <inertia ixx="2.89466199636895E-06" ixy="-9.5524341130118E-18" ixz="7.27101391902106E-16" iyy="1.56064663818156E-06" iyz="-2.24081755790126E-16" izz="1.5606466410806E-06"/>
    </inertial>
    <visual>
      <origin rpy="0 0 0" xyz="0 0 0"/>
      <geometry>
        <mesh filename="package://pir-b-001/meshes/omni1.STL"/>
      </geometry>
      <material name="">
        <color rgba="0.792156862745098 0.819607843137255 0.933333333333333 1"/>
      </material>
    </visual>
    <collision>
      <origin rpy="0 0 0" xyz="0 0 0"/>
      <geometry>
        <mesh filename="package://pir-b-001/meshes/omni1.STL"/>
      </geometry>
    </collision>
  </link>
  <joint name="omni1j" type="continuous">
    <origin rpy="3.14159265358979 0 3.14159265358979" xyz="-0.0489939 0 0"/>
    <parent link="right_Link"/>
    <child link="omni1"/>
    <axis xyz="-1 0 0"/>
    <limit effort="10" velocity="50"/>
  </joint>
  <link name="omni11">
    <inertial>
      <origin rpy="0 0 0" xyz="0.00594999947873641 5.39957731304774E-11 -1.80231940483111E-11"/>
      <mass value="0.0201140567593902"/>
      <inertia ixx="2.89396036741548E-06" ixy="8.33888837112752E-17" ixz="7.38017089766643E-16" iyy="1.56026500386643E-06" iyz="7.65565755138745E-16" izz="1.56026500695539E-06"/>
    </inertial>
    <visual>
      <origin rpy="0 0 0" xyz="0 0 0"/>
      <geometry>
        <mesh filename="package://pir-b-001/meshes/omni11.STL"/>
      </geometry>
      <material name="">
        <color rgba="0.792156862745098 0.819607843137255 0.933333333333333 1"/>
      </material>
    </visual>
    <collision>
      <origin rpy="0 0 0" xyz="0 0 0"/>
      <geometry>
        <mesh filename="package://pir-b-001/meshes/omni11.STL"/>
      </geometry>
    </collision>
  </link>
  <joint name="omni11j" type="continuous">
    <origin rpy="3.14159265358979 0 3.14159265358979" xyz="0.032500000000001 0 0"/>
    <parent link="right_Link"/>
    <child link="omni11"/>
    <axis xyz="-1 0 0"/>
    <limit effort="10" velocity="50"/>
  </joint>
  <link name="left_Link">
    <inertial>
      <origin rpy="0 0 0" xyz="-0.00158846965158471 1.46053958545445E-08 0.0622691284414876"/>
      <mass value="0.167006805501782"/>
      <inertia ixx="8.76796763617996E-05" ixy="-1.08530403468932E-11" ixz="6.66846868785724E-08" iyy="7.49199848156552E-05" iyz="-1.21830500956036E-11" izz="3.62401163602652E-05"/>
    </inertial>
    <visual>
      <origin rpy="0 0 0" xyz="0 0 0"/>
      <geometry>
        <mesh filename="package://pir-b-001/meshes/left_Link.STL"/>
      </geometry>
      <material name="">
        <color rgba="0.2156862745098 0.19607843137255 0.33333333333333 1"/>
      </material>
    </visual>
    <collision>
      <origin rpy="0 0 0" xyz="0 0 0"/>
      <geometry>
        <mesh filename="package://pir-b-001/meshes/left_Link.STL"/>
      </geometry>
    </collision>
  </link>
  <joint name="left_Linkj" type="continuous">
    <origin rpy="1.5707963267949 0 0" xyz="0.0109878 -0.0625 0"/>
    <parent link="base_link"/>
    <child link="left_Link"/>
    <axis xyz="1 0 0"/>
    <limit effort="10" velocity="10"/>
  </joint>
  <link name="link3">
    <inertial>
      <origin rpy="0 0 0" xyz="0.00184881111328213 4.2378468910996E-07 0.0428862642303593"/>
      <mass value="0.0937706135990428"/>
      <inertia ixx="3.3058401223831E-05" ixy="-8.41485245171142E-11" ixz="1.68708890047147E-07" iyy="2.54497427915133E-05" iyz="-1.89306498798599E-10" izz="1.98487722559132E-05"/>
    </inertial>
    <visual>
      <origin rpy="0 0 0" xyz="0 0 0"/>
      <geometry>
        <mesh filename="package://pir-b-001/meshes/link3.STL"/>
      </geometry>
      <material name="">
        <color rgba="0.2156862745098 0.19607843137255 0.33333333333333 1"/>
      </material>
    </visual>
    <collision>
      <origin rpy="0 0 0" xyz="0 0 0"/>
      <geometry>
        <mesh filename="package://pir-b-001/meshes/link3.STL"/>
      </geometry>
    </collision>
  </link>
  <joint name="link3j" type="continuous">
    <origin rpy="0 0 3.14159265358979" xyz="0.0044878 0 0.122"/>
    <parent link="left_Link"/>
    <child link="link3"/>
    <axis xyz="1 0 0"/>
    <limit effort="10" velocity="10"/>
  </joint>
  <link name="left_wheel1">
    <inertial>
      <origin rpy="0 0 0" xyz="-0.000152394722576388 -1.73472347597681E-17 -0.00883686561678922"/>
      <mass value="0.00397466978072403"/>
      <inertia ixx="3.60918483675978E-07" ixy="1.40065332748047E-24" ixz="5.46219029424907E-24" iyy="5.29262126321023E-07" iyz="-2.39172773129062E-13" izz="2.18039563551071E-07"/>
    </inertial>
    <visual>
      <origin rpy="0 0 0" xyz="0 0 0"/>
      <geometry>
        <mesh filename="package://pir-b-001/meshes/left_wheel1.STL"/>
      </geometry>
      <material name="">
        <color rgba="0.792156862745098 0.819607843137255 0.933333333333333 1"/>
      </material>
    </visual>
    <collision>
      <origin rpy="0 0 0" xyz="0 0 0"/>
      <geometry>
        <mesh filename="package://pir-b-001/meshes/left_wheel1.STL"/>
      </geometry>
    </collision>
  </link>
  <joint name="left_wheel1j" type="continuous">
    <origin rpy="0 0 3.14159265358979" xyz="0.0075000000000011 0 0.1211"/>
    <parent link="link3"/>
    <child link="left_wheel1"/>
    <axis xyz="0 0 -1"/>
    <limit effort="10" velocity="50"/>
  </joint>
  <link name="left_wheel">
    <inertial>
      <origin rpy="0 0 0" xyz="0 9.80989711338309E-10 5.4515819636336E-10"/>
      <mass value="0.0631699903417599"/>
      <inertia ixx="2.34601118841818E-05" ixy="-6.34235568100555E-13" ixz="-1.10459970680797E-15" iyy="1.31801476605566E-05" iyz="1.2143448738075E-10" izz="1.31800680409047E-05"/>
    </inertial>
    <visual>
      <origin rpy="0 0 0" xyz="0 0 0"/>
      <geometry>
        <mesh filename="package://pir-b-001/meshes/left_wheel.STL"/>
      </geometry>
      <material name="">
        <color rgba="0.2156862745098 0.25 0.333333333333333 1"/>
      </material>
    </visual>
    <collision>
      <origin rpy="0 0 0" xyz="0 0 0"/>
      <geometry>
        <mesh filename="package://pir-b-001/meshes/left_wheel.STL"/>
      </geometry>
    </collision>
  </link>
  <joint name="left_wheelj" type="continuous">
    <origin rpy="0 0 0" xyz="0 0 0"/>
    <parent link="left_wheel1"/>
    <child link="left_wheel"/>
    <axis xyz="-1 0 0"/>
    <limit effort="0" lower="0" upper="0" velocity="0"/>
  </joint>
  <link name="omni3">
    <inertial>
      <origin rpy="0 0 0" xyz="-0.00906169875747201 9.99316115968263E-11 3.76969983006958E-12"/>
      <mass value="0.0220741125393333"/>
      <inertia ixx="2.90247191554529E-06" ixy="5.7152064424899E-16" ixz="2.06680343176959E-16" iyy="2.42265115370176E-06" iyz="3.86902451094229E-15" izz="2.42265115187895E-06"/>
    </inertial>
    <visual>
      <origin rpy="0 0 0" xyz="0 0 0"/>
      <geometry>
        <mesh filename="package://pir-b-001/meshes/omni3.STL"/>
      </geometry>
      <material name="">
        <color rgba="0.792156862745098 0.819607843137255 0.933333333333333 1"/>
      </material>
    </visual>
    <collision>
      <origin rpy="0 0 0" xyz="0 0 0"/>
      <geometry>
        <mesh filename="package://pir-b-001/meshes/omni3.STL"/>
      </geometry>
    </collision>
  </link>
  <joint name="omni3j" type="continuous">
    <origin rpy="0 0 3.14159265358979" xyz="-0.0325 0 0"/>
    <parent link="link3"/>
    <child link="omni3"/>
    <axis xyz="-1 0 0"/>
    <limit effort="10" velocity="50"/>
  </joint>
  <link name="omni33">
    <inertial>
      <origin rpy="0 0 0" xyz="0.00594999949319272 -1.73031554362435E-12 2.26730509367279E-11"/>
      <mass value="0.0201140568208348"/>
      <inertia ixx="2.89396036823254E-06" ixy="2.0290847722318E-17" ixz="-2.04665204356956E-16" iyy="1.56026500633012E-06" iyz="7.85122891413274E-16" izz="1.56026500750324E-06"/>
    </inertial>
    <visual>
      <origin rpy="0 0 0" xyz="0 0 0"/>
      <geometry>
        <mesh filename="package://pir-b-001/meshes/omni33.STL"/>
      </geometry>
      <material name="">
        <color rgba="0.792156862745098 0.819607843137255 0.933333333333333 1"/>
      </material>
    </visual>
    <collision>
      <origin rpy="0 0 0" xyz="0 0 0"/>
      <geometry>
        <mesh filename="package://pir-b-001/meshes/omni33.STL"/>
      </geometry>
    </collision>
  </link>
  <joint name="omni33j" type="continuous">
    <origin rpy="0 0 3.14159265358979" xyz="0.049487800000001 0 0"/>
    <parent link="link3"/>
    <child link="omni33"/>
    <axis xyz="-1 0 0"/>
    <limit effort="10" velocity="50"/>
  </joint>
  <link name="omni22">
    <inertial>
      <origin rpy="0 0 0" xyz="0.00594999951624568 -5.9256037576727E-12 3.98460431316749E-11"/>
      <mass value="0.0201140568473286"/>
      <inertia ixx="2.89396036649702E-06" ixy="5.90539573515621E-16" ixz="-5.22899163592507E-16" iyy="1.56026500335274E-06" iyz="3.29436237722969E-15" izz="1.56026500968033E-06"/>
    </inertial>
    <visual>
      <origin rpy="0 0 0" xyz="0 0 0"/>
      <geometry>
        <mesh filename="package://pir-b-001/meshes/omni22.STL"/>
      </geometry>
      <material name="">
        <color rgba="0.792156862745098 0.819607843137255 0.933333333333333 1"/>
      </material>
    </visual>
    <collision>
      <origin rpy="0 0 0" xyz="0 0 0"/>
      <geometry>
        <mesh filename="package://pir-b-001/meshes/omni22.STL"/>
      </geometry>
    </collision>
  </link>
  <joint name="omni22j" type="continuous">
    <origin rpy="0 0 0" xyz="-0.0449878 0 0"/>
    <parent link="left_Link"/>
    <child link="omni22"/>
    <axis xyz="1 0 0"/>
    <limit effort="10" velocity="50"/>
  </joint>
  <link name="omni2">
    <inertial>
      <origin rpy="0 0 0" xyz="-0.00906169873200706 -2.22358936818878E-12 -1.69876057665164E-11"/>
      <mass value="0.0220741125868307"/>
      <inertia ixx="2.90247192013343E-06" ixy="8.096473822911E-17" ixz="-1.49131826695456E-16" iyy="2.42265115585034E-06" iyz="-2.80379249301921E-16" izz="2.42265115603564E-06"/>
    </inertial>
    <visual>
      <origin rpy="0 0 0" xyz="0 0 0"/>
      <geometry>
        <mesh filename="package://pir-b-001/meshes/omni2.STL"/>
      </geometry>
      <material name="">
        <color rgba="0.792156862745098 0.819607843137255 0.933333333333333 1"/>
      </material>
    </visual>
    <collision>
      <origin rpy="0 0 0" xyz="0 0 0"/>
      <geometry>
        <mesh filename="package://pir-b-001/meshes/omni2.STL"/>
      </geometry>
    </collision>
  </link>
  <joint name="omni2j" type="continuous">
    <origin rpy="0 0 0" xyz="0.037 0 0"/>
    <parent link="left_Link"/>
    <child link="omni2"/>
    <axis xyz="1 0 0"/>
    <limit effort="10" velocity="50"/>
  </joint>
  <link name="camera_link">
    <inertial>
      <origin rpy="0 0 0" xyz="0 0 0"/>
      <mass value="0.01"/>
      <inertia ixx="0.0001" ixy="0.0" ixz="0.0" iyy="0.001" iyz="0.0" izz="0.0001"/>
    </inertial>
    <visual>
      <origin rpy="0 0 0" xyz="0 0 0"/>
      <geometry>
        <box size="0.04 0.02 0.02"/>
      </geometry>
      <material name="camera_color">
        <color rgba="0.0 1.0 1.0 0.7"/>
      </material>
    </visual>
    <collision>
      <origin rpy="0 0 0" xyz="0 0 0"/>
      <geometry>
        <box size="0.01 0.01 0.01"/>
      </geometry>
    </collision>
  </link>
  <joint name="camera_joint" type="fixed">
    <parent link="right_Link"/>
    <child link="camera_link"/>
    <origin rpy="0 -1.57079632679 -1.57079632679" xyz="-0.0075 0.035 0.05"/>
  </joint>
  <!-- joints transmissions -->
  <transmission name="right_wheel1j_trans">
    <type>transmission_interface/SimpleTransmission</type>
    <joint name="right_wheel1j">
      <hardwareInterface>hardware_interface/EffortJointInterface</hardwareInterface>
    </joint>
    <actuator name="right_wheel1m">
      <mechanicalReduction>1.0</mechanicalReduction>
    </actuator>
  </transmission>
  <transmission name="left_wheel1j_trans">
    <type>transmission_interface/SimpleTransmission</type>
    <joint name="left_wheel1j">
      <hardwareInterface>hardware_interface/EffortJointInterface</hardwareInterface>
    </joint>
    <actuator name="left_wheel1m">
      <mechanicalReduction>1.0</mechanicalReduction>
    </actuator>
  </transmission>
  <transmission name="omni1j_trans">
    <type>transmission_interface/SimpleTransmission</type>
    <joint name="omni1j">
      <hardwareInterface>hardware_interface/EffortJointInterface</hardwareInterface>
    </joint>
    <actuator name="omni1m">
      <mechanicalReduction>1.0</mechanicalReduction>
    </actuator>
  </transmission>
  <transmission name="omni11j_trans">
    <type>transmission_interface/SimpleTransmission</type>
    <joint name="omni11j">
      <hardwareInterface>hardware_interface/EffortJointInterface</hardwareInterface>
    </joint>
    <actuator name="omni11m">
      <mechanicalReduction>1.0</mechanicalReduction>
    </actuator>
  </transmission>
  <transmission name="omni3j_trans">
    <type>transmission_interface/SimpleTransmission</type>
    <joint name="omni3j">
      <hardwareInterface>hardware_interface/EffortJointInterface</hardwareInterface>
    </joint>
    <actuator name="omni3m">
      <mechanicalReduction>1.0</mechanicalReduction>
    </actuator>
  </transmission>
  <transmission name="omni33j_trans">
    <type>transmission_interface/SimpleTransmission</type>
    <joint name="omni33j">
      <hardwareInterface>hardware_interface/EffortJointInterface</hardwareInterface>
    </joint>
    <actuator name="omni33m">
      <mechanicalReduction>1.0</mechanicalReduction>
    </actuator>
  </transmission>
  <gazebo>
    <plugin filename="libgazebo_ros_control.so" name="gazebo_ros_control">
      <robotNamespace>/pir_b_001</robotNamespace>
      <robotSimType>gazebo_ros_control/DefaultRobotHWSim</robotSimType>
    </plugin>
  </gazebo>
  <!-- Torsional Springs -->
  <gazebo reference="right_Linkj">
    <!-- <implicitSpringDamper>true</implicitSpringDamper>
  <erp>0.2</erp>
  <cfm>0.01</cfm> -->
    <springStiffness>1.0</springStiffness>
    <springReference>0.0</springReference>
    <damping>10.0</damping>
  </gazebo>
  <gazebo reference="left_Linkj">
    <!-- <implicitSpringDamper>true</implicitSpringDamper>
  <erp>0.2</erp>
  <cfm>0.01</cfm> -->
    <springStiffness>1.0</springStiffness>
    <springReference>0.0</springReference>
    <damping>10.0</damping>
  </gazebo>
  <gazebo reference="link3j">
    <!-- <implicitSpringDamper>true</implicitSpringDamper>
  <erp>0.2</erp>
  <cfm>0.01</cfm> -->
    <springStiffness>1.0</springStiffness>
    <springReference>0.0</springReference>
    <damping>10.0</damping>
  </gazebo>
  <!-- Links on Gazebo -->
  <gazebo reference="omni1">
    <mu1 value="0.5"/>
    <mu2 value="0.7"/>
    <material>Gazebo/Black</material>
  </gazebo>
  <gazebo reference="omni11">
    <mu1 value="0.5"/>
    <mu2 value="0.7"/>
    <material>Gazebo/Black</material>
  </gazebo>
  <gazebo reference="omni3">
    <mu1 value="0.5"/>
    <mu2 value="0.7"/>
    <material>Gazebo/Black</material>
  </gazebo>
  <gazebo reference="omni33">
    <mu1 value="0.5"/>
    <mu2 value="0.7"/>
    <material>Gazebo/Black</material>
  </gazebo>
  <gazebo reference="omni2">
    <mu1 value="0.5"/>
    <mu2 value="0.7"/>
    <material>Gazebo/Black</material>
  </gazebo>
  <gazebo reference="omni22">
    <mu1 value="0.5"/>
    <mu2 value="0.7"/>
    <material>Gazebo/Black</material>
  </gazebo>
  <gazebo reference="right_wheel">
    <mu1 value="0.5"/>
    <mu2 value="0.7"/>
    <material>Gazebo/DarkGrey</material>
  </gazebo>
  <gazebo reference="left_wheel">
    <mu1 value="0.5"/>
    <mu2 value="0.7"/>
    <material>Gazebo/DarkGrey</material>
  </gazebo>
  <gazebo reference="right_Link">
    <material>Gazebo/ZincYellow</material>
    <!-- <dampingFactor>0.1</dampingFactor> -->
  </gazebo>
  <gazebo reference="left_Link">
    <material>Gazebo/ZincYellow</material>
    <!-- <dampingFactor>0.1</dampingFactor> -->
  </gazebo>
  <gazebo reference="link3">
    <material>Gazebo/ZincYellow</material>
    <!-- <dampingFactor>0.1</dampingFactor> -->
  </gazebo>
  <gazebo reference="base_link">
    <material>Gazebo/ZincYellow</material>
    <!-- <dampingFactor>0.1</dampingFactor> -->
  </gazebo>
  <gazebo reference="camera_link">
    <material>Gazebo/YellowGlow</material>
  </gazebo>
  <!-- Camera Sensor -->
  <gazebo reference="camera_link">
    <sensor name="camera" type="camera">
      <update_rate>30.0</update_rate>
      <camera name="head">
        <horizontal_fov>1.3962634</horizontal_fov>
        <image>
          <width>800</width>
          <height>800</height>
          <format>R8G8B8</format>
        </image>
        <clip>
          <near>0.02</near>
          <far>300</far>
        </clip>
        <noise>
          <type>gaussian</type>
          <mean>0.0</mean>
          <stddev>0.007</stddev>
        </noise>
      </camera>
      <plugin filename="libgazebo_ros_camera.so" name="camera_controller">
        <alwaysOn>true</alwaysOn>
        <updateRate>30.0</updateRate>
        <cameraName>camera</cameraName>
        <imageTopicName>image_raw</imageTopicName>
        <cameraInfoTopicName>camera_info</cameraInfoTopicName>
        <frameName>camera_link</frameName>
        <hackBaseline>0.07</hackBaseline>
        <distortionK1>0.0</distortionK1>
        <distortionK2>0.0</distortionK2>
        <distortionK3>0.0</distortionK3>
        <distortionT1>0.0</distortionT1>
        <distortionT2>0.0</distortionT2>
      </plugin>
    </sensor>
  </gazebo>
</robot>

